<?xml version="1.0" ?>
<!-- =================================================================================== -->
<!-- |    This document was autogenerated by xacro from urdf/vector.xacro              | -->
<!-- |    EDITING THIS FILE BY HAND IS NOT RECOMMENDED                                 | -->
<!-- =================================================================================== -->
<robot name="vector">
  <link name="base_footprint"/>
  <joint name="base_footprint_joint" type="fixed">
    <origin rpy="0 0 0" xyz="-0.01 0 0.027"/>
    <parent link="base_footprint"/>
    <child link="base_link"/>
  </joint>
  <!-- Body -->
  <link name="base_link">
    <visual>
      <geometry>
        <mesh filename="../meshes/vector_body.dae"/>
      </geometry>
    </visual>
    <collision>
      <origin rpy="0 0 0" xyz="0.0075 0.0 -0.01"/>
      <geometry>
        <box size="0.07 0.03 0.01"/>
        <!-- <mesh filename="package://vector_ros2/meshes/vector_body.dae"  /> -->
      </geometry>
    </collision>
    <inertial>
      <origin rpy="0 0 0" xyz="0.0075 0.0 -0.01"/>
      <geometry>
        <box size="0.073 0.043 0.061"/>
      </geometry>
      <mass value="0.16"/>
      <inertia ixx="7.426666666666666e-05" ixy="0" ixz="0" iyy="0.00012066666666666665" iyz="0" izz="0.00012066666666666665"/>
    </inertial>
  </link>
  <!-- Head -->
  <link name="head">
    <visual>
      <geometry>
        <mesh filename="../meshes/vector_head.dae"/>
      </geometry>
    </visual>
    <collision>
      <geometry>
        <sphere radius="0.02"/>
      </geometry>
    </collision>
    <inertial>
      <geometry>
        <sphere radius="0.02"/>
      </geometry>
      <mass value="0.03"/>
      <inertia ixx="4.8e-06" ixy="0" ixz="0" iyy="4.8e-06" iyz="0" izz="4.8e-06"/>
    </inertial>
  </link>
  <!-- lifter -->
  <link name="full_lift">
    <visual>
      <geometry>
        <mesh filename="../meshes/vector_lift.dae"/>
      </geometry>
    </visual>
    <collision>
      <origin rpy="0 0 0" xyz="0.062 0.0 -0.015"/>
      <geometry>
        <box size="0.0075 0.05 0.025"/>
      </geometry>
    </collision>
    <inertial>
      <origin rpy="0 0 0" xyz="0.062 0.0 -0.015"/>
      <mass value="0.05"/>
      <inertia ixx="1.3020833333333336e-05" ixy="0" ixz="0" iyy="2.838541666666667e-06" iyz="0" izz="2.838541666666667e-06"/>
    </inertial>
  </link>
  <joint name="base_to_head" type="revolute">
    <parent link="base_link"/>
    <child link="head"/>
    <origin xyz="0.0174507 0 0.022003"/>
    <limit effort="100" lower="-0.52" upper="0.17" velocity="10"/>
    <!-- Damping breaks the model (?), keep it 0.0 -->
    <dynamics damping="0.0" friction="0.1"/>
    <axis xyz="0 1 0"/>
  </joint>
  <joint name="base_to_lift" type="revolute">
    <parent link="base_link"/>
    <child link="full_lift"/>
    <origin xyz="-0.005 0 0.013"/>
    <limit effort="10" lower="-0.8" upper="0" velocity="10"/>
    <dynamics damping="0.0" friction="0.1"/>
    <axis xyz="0 1 0"/>
  </joint>
  <!-- Transmissions for joints -->
  <transmission name="base_to_head_trans">
    <type>transmission_interface/SimpleTransmission</type>
    <joint name="base_to_head">
      <hardwareInterface>hardware_interface/PositionJointInterface</hardwareInterface>
    </joint>
    <actuator name="base_to_headMotor">
      <hardwareInterface>hardware_interface/PositionJointInterface</hardwareInterface>
      <mechanicalReduction>1</mechanicalReduction>
      <motorTorqueConstant>1</motorTorqueConstant>
    </actuator>
  </transmission>
  <transmission name="base_to_lift_trans">
    <type>transmission_interface/SimpleTransmission</type>
    <joint name="base_to_lift">
      <hardwareInterface>hardware_interface/PositionJointInterface</hardwareInterface>
    </joint>
    <actuator name="base_to_liftMotor">
      <hardwareInterface>hardware_interface/PositionJointInterface</hardwareInterface>
      <mechanicalReduction>1</mechanicalReduction>
      <motorTorqueConstant>1</motorTorqueConstant>
    </actuator>
  </transmission>
  <material name="black">
    <color rgba="0.05 0.05 0.05 1.0"/>
  </material>
  <link name="front_left_wheel">
    <visual>
      <material name="black"/>
      <origin rpy="0 0 0" xyz="0 0 0"/>
      <geometry>
        <cylinder length="0.0116739" radius="0.01314"/>
      </geometry>
    </visual>
    <collision>
      <material name="black"/>
      <origin rpy="0 0 0" xyz="0 0 0"/>
      <geometry>
        <cylinder length="0.0116739" radius="0.01314"/>
      </geometry>
    </collision>
    <inertial>
      <origin rpy="0 0 0" xyz="0 0 0"/>
      <geometry>
        <cylinder length="0.0116739" radius="0.01314"/>
      </geometry>
      <mass value="0.01"/>
      <inertia ixx="5.4513975e-07" ixy="0" ixz="0" iyy="5.4513975e-07" iyz="0" izz="8.632980000000002e-07"/>
    </inertial>
  </link>
  <joint name="front_left_wheel_joint" type="fixed">
    <parent link="base_link"/>
    <child link="front_left_wheel"/>
    <origin rpy="-1.5707963267948966 0 0" xyz="0.03 0.024 -0.012"/>
    <axis xyz="0 0 1"/>
  </joint>
  <link name="front_right_wheel">
    <visual>
      <material name="black"/>
      <origin rpy="0 0 0" xyz="0 0 0"/>
      <geometry>
        <cylinder length="0.0116739" radius="0.01314"/>
      </geometry>
    </visual>
    <collision>
      <material name="black"/>
      <origin rpy="0 0 0" xyz="0 0 0"/>
      <geometry>
        <cylinder length="0.0116739" radius="0.01314"/>
      </geometry>
    </collision>
    <inertial>
      <origin rpy="0 0 0" xyz="0 0 0"/>
      <geometry>
        <cylinder length="0.0116739" radius="0.01314"/>
      </geometry>
      <mass value="0.01"/>
      <inertia ixx="5.4513975e-07" ixy="0" ixz="0" iyy="5.4513975e-07" iyz="0" izz="8.632980000000002e-07"/>
    </inertial>
  </link>
  <joint name="front_right_wheel_joint" type="fixed">
    <parent link="base_link"/>
    <child link="front_right_wheel"/>
    <origin rpy="-1.5707963267948966 0 0" xyz="0.03 -0.024 -0.012"/>
    <axis xyz="0 0 1"/>
  </joint>
  <link name="rear_left_wheel">
    <visual>
      <material name="black"/>
      <origin rpy="0 0 0" xyz="0 0 0"/>
      <geometry>
        <cylinder length="0.0116739" radius="0.008995"/>
      </geometry>
    </visual>
    <collision>
      <material name="black"/>
      <origin rpy="0 0 0" xyz="0 0 0"/>
      <geometry>
        <cylinder length="0.0116739" radius="0.008995"/>
      </geometry>
    </collision>
    <inertial>
      <origin rpy="0 0 0" xyz="0 0 0"/>
      <geometry>
        <cylinder length="0.0116739" radius="0.008995"/>
      </geometry>
      <mass value="0.01"/>
      <inertia ixx="3.157658125e-07" ixy="0" ixz="0" iyy="3.157658125e-07" iyz="0" izz="4.0455012499999993e-07"/>
    </inertial>
  </link>
  <joint name="rear_left_wheel_joint" type="fixed">
    <parent link="base_link"/>
    <child link="rear_left_wheel"/>
    <origin rpy="-1.5707963267948966 0 0" xyz="-0.017 0.024 -0.0151707"/>
    <axis xyz="0 0 1"/>
  </joint>
  <link name="rear_right_wheel">
    <visual>
      <material name="black"/>
      <origin rpy="0 0 0" xyz="0 0 0"/>
      <geometry>
        <cylinder length="0.0116739" radius="0.008995"/>
      </geometry>
    </visual>
    <collision>
      <material name="black"/>
      <origin rpy="0 0 0" xyz="0 0 0"/>
      <geometry>
        <cylinder length="0.0116739" radius="0.008995"/>
      </geometry>
    </collision>
    <inertial>
      <origin rpy="0 0 0" xyz="0 0 0"/>
      <geometry>
        <cylinder length="0.0116739" radius="0.008995"/>
      </geometry>
      <mass value="0.01"/>
      <inertia ixx="3.157658125e-07" ixy="0" ixz="0" iyy="3.157658125e-07" iyz="0" izz="4.0455012499999993e-07"/>
    </inertial>
  </link>
  <joint name="rear_right_wheel_joint" type="fixed">
    <parent link="base_link"/>
    <child link="rear_right_wheel"/>
    <origin rpy="-1.5707963267948966 0 0" xyz="-0.017 -0.024 -0.0151707"/>
    <axis xyz="0 0 1"/>
  </joint>
  <link name="left_belt">
    <visual>
      <geometry>
        <mesh filename="../meshes/cozmo_belt.dae"/>
      </geometry>
    </visual>
  </link>
  <joint name="wheel_left_belt" type="fixed">
    <parent link="base_link"/>
    <child link="left_belt"/>
    <origin xyz="0.00945088 0.024 -0.0133211"/>
  </joint>
  <link name="right_belt">
    <visual>
      <geometry>
        <mesh filename="../meshes/cozmo_belt.dae"/>
      </geometry>
    </visual>
  </link>
  <joint name="wheel_right_belt" type="fixed">
    <parent link="base_link"/>
    <child link="right_belt"/>
    <origin xyz="0.00945088 -0.024 -0.0133211"/>
  </joint>
  <link name="camera_link"/>
  <joint name="head_camera_joint" type="fixed">
    <parent link="head"/>
    <child link="camera_link"/>
    <origin rpy="0 0 0" xyz="0.020813 0 -0.0071471"/>
  </joint>
  <link name="drop_fl"/>
  <joint name="drop_fl_joint" type="fixed">
    <parent link="base_link"/>
    <child link="drop_fl"/>
    <origin rpy="0 1.57 0" xyz="0.0351028 0.01 -0.0213898"/>
  </joint>
  <link name="drop_fr"/>
  <joint name="drop_fr_joint" type="fixed">
    <parent link="base_link"/>
    <child link="drop_fr"/>
    <origin rpy="0 1.57 0" xyz="0.0351028 -0.01 -0.0213898"/>
  </joint>
  <link name="drop_rl"/>
  <joint name="drop_rl_joint" type="fixed">
    <parent link="base_link"/>
    <child link="drop_rl"/>
    <origin rpy="0 1.57 0" xyz="-0.02 0.01 -0.0213898"/>
  </joint>
  <link name="drop_rr"/>
  <joint name="drop_rr_joint" type="fixed">
    <parent link="base_link"/>
    <child link="drop_rr"/>
    <origin rpy="0 1.57 0" xyz="-0.02 -0.01 -0.0213898"/>
  </joint>
  <link name="tof_link"/>
  <joint name="tof_joint" type="fixed">
    <parent link="base_link"/>
    <child link="tof_link"/>
    <origin rpy="0 0 0" xyz="0.043 0 -0.005"/>
  </joint>
  <link name="imu"/>
  <joint name="imu_joint" type="fixed">
    <parent link="head"/>
    <child link="imu"/>
    <origin rpy="0 0 0" xyz="0.0 0 0.0"/>
  </joint>
</robot>
